ERROR 2024-09-03 19:46:58,237 views Error retrieving blog posts: no such table: blog_blog
ERROR 2024-09-03 19:49:03,648 views Error retrieving blog posts: no such table: blog_blog
ERROR 2024-09-03 19:53:54,581 views Error retrieving blog posts: no such table: blog_blog
ERROR 2024-09-03 19:55:32,572 views Error retrieving blog posts: no such table: blog_blog
ERROR 2024-09-03 19:56:44,380 views Error retrieving blog posts: no such table: blog_blog
ERROR 2024-09-03 19:56:45,955 views Error retrieving blog posts: no such table: blog_blog
ERROR 2024-09-03 19:56:58,233 views Error retrieving blog posts: no such table: blog_blog
ERROR 2024-09-03 19:57:00,516 views Error retrieving blog posts: no such table: blog_blog
ERROR 2024-09-03 19:58:22,358 views Error retrieving blog posts: no such table: blog_blog
ERROR 2024-09-03 19:58:31,317 views Error retrieving blog posts: no such table: blog_blog
ERROR 2024-09-03 19:59:44,824 views Error retrieving blog posts: no such table: blog_blog
ERROR 2024-09-03 20:03:24,570 views Error retrieving blog posts: no such table: blog_blog
Traceback (most recent call last):
  File "D:\Shailendra Shetty3\Django_Projects\blog\.venv\Lib\site-packages\django\db\backends\utils.py", line 105, in _execute
    return self.cursor.execute(sql, params)
           ^^^^^^^^^^^^^^^^^^^^^^^^^^^^^^^^
  File "D:\Shailendra Shetty3\Django_Projects\blog\.venv\Lib\site-packages\django\db\backends\sqlite3\base.py", line 354, in execute
    return super().execute(query, params)
           ^^^^^^^^^^^^^^^^^^^^^^^^^^^^^^
sqlite3.OperationalError: no such table: blog_blog

The above exception was the direct cause of the following exception:

Traceback (most recent call last):
  File "D:\Shailendra Shetty3\Django_Projects\blog\blog\blog\views.py", line 64, in blog_post_list
    return Response(serializer.data)
                    ^^^^^^^^^^^^^^^
  File "D:\Shailendra Shetty3\Django_Projects\blog\.venv\Lib\site-packages\rest_framework\serializers.py", line 795, in data
    ret = super().data
          ^^^^^^^^^^^^
  File "D:\Shailendra Shetty3\Django_Projects\blog\.venv\Lib\site-packages\rest_framework\serializers.py", line 249, in data
    self._data = self.to_representation(self.instance)
                 ^^^^^^^^^^^^^^^^^^^^^^^^^^^^^^^^^^^^^
  File "D:\Shailendra Shetty3\Django_Projects\blog\.venv\Lib\site-packages\rest_framework\serializers.py", line 713, in to_representation
    return [
           ^
  File "D:\Shailendra Shetty3\Django_Projects\blog\.venv\Lib\site-packages\django\db\models\query.py", line 400, in __iter__
    self._fetch_all()
  File "D:\Shailendra Shetty3\Django_Projects\blog\.venv\Lib\site-packages\django\db\models\query.py", line 1928, in _fetch_all
    self._result_cache = list(self._iterable_class(self))
                         ^^^^^^^^^^^^^^^^^^^^^^^^^^^^^^^^
  File "D:\Shailendra Shetty3\Django_Projects\blog\.venv\Lib\site-packages\django\db\models\query.py", line 91, in __iter__
    results = compiler.execute_sql(
              ^^^^^^^^^^^^^^^^^^^^^
  File "D:\Shailendra Shetty3\Django_Projects\blog\.venv\Lib\site-packages\django\db\models\sql\compiler.py", line 1574, in execute_sql
    cursor.execute(sql, params)
  File "D:\Shailendra Shetty3\Django_Projects\blog\.venv\Lib\site-packages\django\db\backends\utils.py", line 122, in execute
    return super().execute(sql, params)
           ^^^^^^^^^^^^^^^^^^^^^^^^^^^^
  File "D:\Shailendra Shetty3\Django_Projects\blog\.venv\Lib\site-packages\django\db\backends\utils.py", line 79, in execute
    return self._execute_with_wrappers(
           ^^^^^^^^^^^^^^^^^^^^^^^^^^^^
  File "D:\Shailendra Shetty3\Django_Projects\blog\.venv\Lib\site-packages\django\db\backends\utils.py", line 92, in _execute_with_wrappers
    return executor(sql, params, many, context)
           ^^^^^^^^^^^^^^^^^^^^^^^^^^^^^^^^^^^^
  File "D:\Shailendra Shetty3\Django_Projects\blog\.venv\Lib\site-packages\django\db\backends\utils.py", line 100, in _execute
    with self.db.wrap_database_errors:
  File "D:\Shailendra Shetty3\Django_Projects\blog\.venv\Lib\site-packages\django\db\utils.py", line 91, in __exit__
    raise dj_exc_value.with_traceback(traceback) from exc_value
  File "D:\Shailendra Shetty3\Django_Projects\blog\.venv\Lib\site-packages\django\db\backends\utils.py", line 105, in _execute
    return self.cursor.execute(sql, params)
           ^^^^^^^^^^^^^^^^^^^^^^^^^^^^^^^^
  File "D:\Shailendra Shetty3\Django_Projects\blog\.venv\Lib\site-packages\django\db\backends\sqlite3\base.py", line 354, in execute
    return super().execute(query, params)
           ^^^^^^^^^^^^^^^^^^^^^^^^^^^^^^
django.db.utils.OperationalError: no such table: blog_blog
ERROR 2024-09-03 20:05:05,527 views Error creating blog post: no such table: blog_blog
Traceback (most recent call last):
  File "D:\Shailendra Shetty3\Django_Projects\blog\.venv\Lib\site-packages\django\db\backends\utils.py", line 105, in _execute
    return self.cursor.execute(sql, params)
           ^^^^^^^^^^^^^^^^^^^^^^^^^^^^^^^^
  File "D:\Shailendra Shetty3\Django_Projects\blog\.venv\Lib\site-packages\django\db\backends\sqlite3\base.py", line 354, in execute
    return super().execute(query, params)
           ^^^^^^^^^^^^^^^^^^^^^^^^^^^^^^
sqlite3.OperationalError: no such table: blog_blog

The above exception was the direct cause of the following exception:

Traceback (most recent call last):
  File "D:\Shailendra Shetty3\Django_Projects\blog\blog\blog\views.py", line 73, in blog_post_list
    serializer.save()
  File "D:\Shailendra Shetty3\Django_Projects\blog\.venv\Lib\site-packages\rest_framework\serializers.py", line 208, in save
    self.instance = self.create(validated_data)
                    ^^^^^^^^^^^^^^^^^^^^^^^^^^^
  File "D:\Shailendra Shetty3\Django_Projects\blog\.venv\Lib\site-packages\rest_framework\serializers.py", line 989, in create
    instance = ModelClass._default_manager.create(**validated_data)
               ^^^^^^^^^^^^^^^^^^^^^^^^^^^^^^^^^^^^^^^^^^^^^^^^^^^^
  File "D:\Shailendra Shetty3\Django_Projects\blog\.venv\Lib\site-packages\django\db\models\manager.py", line 87, in manager_method
    return getattr(self.get_queryset(), name)(*args, **kwargs)
           ^^^^^^^^^^^^^^^^^^^^^^^^^^^^^^^^^^^^^^^^^^^^^^^^^^^
  File "D:\Shailendra Shetty3\Django_Projects\blog\.venv\Lib\site-packages\django\db\models\query.py", line 679, in create
    obj.save(force_insert=True, using=self.db)
  File "D:\Shailendra Shetty3\Django_Projects\blog\.venv\Lib\site-packages\django\db\models\base.py", line 891, in save
    self.save_base(
  File "D:\Shailendra Shetty3\Django_Projects\blog\.venv\Lib\site-packages\django\db\models\base.py", line 997, in save_base
    updated = self._save_table(
              ^^^^^^^^^^^^^^^^^
  File "D:\Shailendra Shetty3\Django_Projects\blog\.venv\Lib\site-packages\django\db\models\base.py", line 1160, in _save_table
    results = self._do_insert(
              ^^^^^^^^^^^^^^^^
  File "D:\Shailendra Shetty3\Django_Projects\blog\.venv\Lib\site-packages\django\db\models\base.py", line 1201, in _do_insert
    return manager._insert(
           ^^^^^^^^^^^^^^^^
  File "D:\Shailendra Shetty3\Django_Projects\blog\.venv\Lib\site-packages\django\db\models\manager.py", line 87, in manager_method
    return getattr(self.get_queryset(), name)(*args, **kwargs)
           ^^^^^^^^^^^^^^^^^^^^^^^^^^^^^^^^^^^^^^^^^^^^^^^^^^^
  File "D:\Shailendra Shetty3\Django_Projects\blog\.venv\Lib\site-packages\django\db\models\query.py", line 1847, in _insert
    return query.get_compiler(using=using).execute_sql(returning_fields)
           ^^^^^^^^^^^^^^^^^^^^^^^^^^^^^^^^^^^^^^^^^^^^^^^^^^^^^^^^^^^^^
  File "D:\Shailendra Shetty3\Django_Projects\blog\.venv\Lib\site-packages\django\db\models\sql\compiler.py", line 1836, in execute_sql
    cursor.execute(sql, params)
  File "D:\Shailendra Shetty3\Django_Projects\blog\.venv\Lib\site-packages\django\db\backends\utils.py", line 122, in execute
    return super().execute(sql, params)
           ^^^^^^^^^^^^^^^^^^^^^^^^^^^^
  File "D:\Shailendra Shetty3\Django_Projects\blog\.venv\Lib\site-packages\django\db\backends\utils.py", line 79, in execute
    return self._execute_with_wrappers(
           ^^^^^^^^^^^^^^^^^^^^^^^^^^^^
  File "D:\Shailendra Shetty3\Django_Projects\blog\.venv\Lib\site-packages\django\db\backends\utils.py", line 92, in _execute_with_wrappers
    return executor(sql, params, many, context)
           ^^^^^^^^^^^^^^^^^^^^^^^^^^^^^^^^^^^^
  File "D:\Shailendra Shetty3\Django_Projects\blog\.venv\Lib\site-packages\django\db\backends\utils.py", line 100, in _execute
    with self.db.wrap_database_errors:
  File "D:\Shailendra Shetty3\Django_Projects\blog\.venv\Lib\site-packages\django\db\utils.py", line 91, in __exit__
    raise dj_exc_value.with_traceback(traceback) from exc_value
  File "D:\Shailendra Shetty3\Django_Projects\blog\.venv\Lib\site-packages\django\db\backends\utils.py", line 105, in _execute
    return self.cursor.execute(sql, params)
           ^^^^^^^^^^^^^^^^^^^^^^^^^^^^^^^^
  File "D:\Shailendra Shetty3\Django_Projects\blog\.venv\Lib\site-packages\django\db\backends\sqlite3\base.py", line 354, in execute
    return super().execute(query, params)
           ^^^^^^^^^^^^^^^^^^^^^^^^^^^^^^
django.db.utils.OperationalError: no such table: blog_blog
